Workbook

Sheet 指标结果_数值源
A1: date | B1: route_name | C1: value | D1: unit | E1: quality_level | F1: p25 | G1: p50 | H1: p75 | I1: p85 | J1: p90 | K1: p95 | L1: p99 | M1: wow_pct | N1: z_score | O1: up_streak_weeks | P1: warning_tags | Q1: warning_level | R1: source_note
A2: 2025-11-28 | B2: 欧洲航线 | C2: 1404 | D2: USD/TEU | E2: B_public_excerpt | F2: 1472.25 | G2: 1550.38 | H2: 1618.56 | I2: 1648.44 | J2: 1678.12 | K2: 1784.5 | L2: 1882.75 | N2: -1.22 | O2: 0 | P2: 无 | Q2: 正常 | R2: 来自现有SCFI真实/公开线索与演示补全长表；C_demo_interpolation不作真实事实声明
A3: 2025-12-05 | B3: 欧洲航线 | C3: 1400 | D3: USD/TEU | E3: B_public_excerpt | F3: 1472.25 | G3: 1550.38 | H3: 1618.56 | I3: 1648.44 | J3: 1678.12 | K3: 1784.5 | L3: 1882.75 | M3: -0.28 | N3: -1.26 | O3: 0 | P3: 无 | Q3: 正常 | R3: 来自现有SCFI真实/公开线索与演示补全长表；C_demo_interpolation不作真实事实声明
A4: 2025-12-12 | B4: 欧洲航线 | C4: 1466.5 | D4: USD/TEU | E4: C_demo_interpolation | F4: 1472.25 | G4: 1550.38 | H4: 1618.56 | I4: 1648.44 | J4: 1678.12 | K4: 1784.5 | L4: 1882.75 | M4: 4.75 | N4: -0.73 | O4: 1 | P4: 无 | Q4: 正常 | R4: 来自现有SCFI真实/公开线索与演示补全长表；C_demo_interpolation不作真实事实声明
A5: 2025-12-19 | B5: 欧洲航线 | C5: 1533 | D5: USD/TEU | E5: B_public_excerpt | F5: 1472.25 | G5: 1550.38 | H5: 1618.56 | I5: 1648.44 | J5: 1678.12 | K5: 1784.5 | L5: 1882.75 | M5: 4.53 | N5: -0.2 | O5: 2 | P5: 无 | Q5: 正常 | R5: 来自现有SCFI真实/公开线索与演示补全长表；C_demo_interpolation不作真实事实声明
A6: 2025-12-26 | B6: 欧洲航线 | C6: 1690 | D6: USD/TEU | E6: B_public_excerpt | F6: 1472.25 | G6: 1550.38 | H6: 1618.56 | I6: 1648.44 | J6: 1678.12 | K6: 1784.5 | L6: 1882.75 | M6: 10.24 | N6: 1.05 | O6: 3 | P6: P85关注;周涨幅≥10%;连续上涨≥3周 | Q6: 黄色关注 | R6: 来自现有SCFI真实/公开线索与演示补全长表；C_demo_interpolation不作真实事实声明
A7: 2026-01-02 | B7: 欧洲航线 | C7: 1666.25 | D7: USD/TEU | E7: C_demo_interpolation | F7: 1472.25 | G7: 1550.38 | H7: 1618.56 | I7: 1648.44 | J7: 1678.12 | K7: 1784.5 | L7: 1882.75 | M7: -1.41 | N7: 0.86 | O7: 0 | P7: P85关注 | Q7: 黄色关注 | R7: 来自现有SCFI真实/公开线索与演示补全长表；C_demo_interpolation不作真实事实声明
A8: 2026-01-09 | B8: 欧洲航线 | C8: 1642.5 | D8: USD/TEU | E8: C_demo_interpolation | F8: 1472.25 | G8: 1550.38 | H8: 1618.56 | I8: 1648.44 | J8: 1678.12 | K8: 1784.5 | L8: 1882.75 | M8: -1.43 | N8: 0.67 | O8: 0 | P8: 无 | Q8: 正常 | R8: 来自现有SCFI真实/公开线索与演示补全长表；C_demo_interpolation不作真实事实声明
A9: 2026-01-16 | B9: 欧洲航线 | C9: 1618.75 | D9: USD/TEU | E9: C_demo_interpolation | F9: 1472.25 | G9: 1550.38 | H9: 1618.56 | I9: 1648.44 | J9: 1678.12 | K9: 1784.5 | L9: 1882.75 | M9: -1.45 | N9: 0.48 | O9: 0 | P9: 无 | Q9: 正常 | R9: 来自现有SCFI真实/公开线索与演示补全长表；C_demo_interpolation不作真实事实声明
A10: 2026-01-23 | B10: 欧洲航线 | C10: 1595 | D10: USD/TEU | E10: B_public_excerpt | F10: 1472.25 | G10: 1550.38 | H10: 1618.56 | I10: 1648.44 | J10: 1678.12 | K10: 1784.5 | L10: 1882.75 | M10: -1.47 | N10: 0.29 | O10: 0 | P10: 无 | Q10: 正常 | R10: 来自现有SCFI真实/公开线索与演示补全长表；C_demo_interpolation不作真实事实声明
A11: 2026-01-30 | B11: 欧洲航线 | C11: 1418 | D11: USD/TEU | E11: B_public_excerpt | F11: 1472.25 | G11: 1550.38 | H11: 1618.56 | I11: 1648.44 | J11: 1678.12 | K11: 1784.5 | L11: 1882.75 | M11: -11.1 | N11: -1.11 | O11: 0 | P11: 无 | Q11: 正常 | R11: 来自现有SCFI真实/公开线索与演示补全长表；C_demo_interpolation不作真实事实声明
A12: 2026-02-06 | B12: 欧洲航线 | C12: 1403 | D12: USD/TEU | E12: B_public_excerpt | F12: 1472.25 | G12: 1550.38 | H12: 1618.56 | I12: 1648.44 | J12: 1678.12 | K12: 1784.5 | L12: 1882.75 | M12: -1.06 | N12: -1.23 | O12: 0 | P12: 无 | Q12: 正常 | R12: 来自现有SCFI真实/公开线索与演示补全长表；C_demo_interpolation不作真实事实声明
A13: 2026-02-13 | B13: 欧洲航线 | C13: 1361 | D13: USD/TEU | E13: B_public_excerpt | F13: 1472.25 | G13: 1550.38 | H13: 1618.56 | I13: 1648.44 | J13: 1678.12 | K13: 1784.5 | L13: 1882.75 | M13: -2.99 | N13: -1.57 | O13: 0 | P13: 无 | Q13: 正常 | R13: 来自现有SCFI真实/公开线索与演示补全长表；C_demo_interpolation不作真实事实声明
A14: 2026-02-20 | B14: 欧洲航线 | C14: 1425.25 | D14: USD/TEU | E14: C_demo_interpolation | F14: 1472.25 | G14: 1550.38 | H14: 1618.56 | I14: 1648.44 | J14: 1678.12 | K14: 1784.5 | L14: 1882.75 | M14: 4.72 | N14: -1.06 | O14: 1 | P14: 无 | Q14: 正常 | R14: 来自现有SCFI真实/公开线索与演示补全长表；C_demo_interpolation不作真实事实声明
... A27: 2026-05-22 | B27: 欧洲航线 | C27: 1905 | D27: USD/TEU | E27: A_official | F27: 1472.25 | G27: 1550.38 | H27: 1618.56 | I27: 1648.44 | J27: 1678.12 | K27: 1784.5 | L27: 1882.75 | M27: 4.9 | N27: 2.76 | O27: 4 | P27: P95高位;Z≥2异常;连续上涨≥3周 | Q27: 红色预警 | R27: 来自现有SCFI真实/公开线索与演示补全长表；C_demo_interpolation不作真实事实声明
A28: 2025-11-28 | B28: 地中海航线 | C28: 2232 | D28: USD/TEU | E28: B_public_excerpt | F28: 2304.51 | G28: 2432.75 | H28: 2675.65 | I28: 2891.35 | J28: 3071.1 | K28: 3144.5 | L28: 3191.5 | N28: -1.01 | O28: 0 | P28: 无 | Q28: 正常 | R28: 来自现有SCFI真实/公开线索与演示补全长表；C_demo_interpolation不作真实事实声明
A29: 2025-12-05 | B29: 地中海航线 | C29: 2300 | D29: USD/TEU | E29: B_public_excerpt | F29: 2304.51 | G29: 2432.75 | H29: 2675.65 | I29: 2891.35 | J29: 3071.1 | K29: 3144.5 | L29: 3191.5 | M29: 3.05 | N29: -0.78 | O29: 1 | P29: 无 | Q29: 正常 | R29: 来自现有SCFI真实/公开线索与演示补全长表；C_demo_interpolation不作真实事实声明
A30: 2025-12-12 | B30: 地中海航线 | C30: 2566.5 | D30: USD/TEU | E30: C_demo_interpolation | F30: 2304.51 | G30: 2432.75 | H30: 2675.65 | I30: 2891.35 | J30: 3071.1 | K30: 3144.5 | L30: 3191.5 | M30: 11.59 | N30: 0.1 | O30: 2 | P30: 周涨幅≥10% | Q30: 黄色关注 | R30: 来自现有SCFI真实/公开线索与演示补全长表；C_demo_interpolation不作真实事实声明
A31: 2025-12-19 | B31: 地中海航线 | C31: 2833 | D31: USD/TEU | E31: B_public_excerpt | F31: 2304.51 | G31: 2432.75 | H31: 2675.65 | I31: 2891.35 | J31: 3071.1 | K31: 3144.5 | L31: 3191.5 | M31: 10.38 | N31: 0.98 | O31: 3 | P31: 周涨幅≥10%;连续上涨≥3周 | Q31: 黄色关注 | R31: 来自现有SCFI真实/公开线索与演示补全长表；C_demo_interpolation不作真实事实声明
A32: 2025-12-26 | B32: 地中海航线 | C32: 3143 | D32: USD/TEU | E32: B_public_excerpt | F32: 2304.51 | G32: 2432.75 | H32: 2675.65 | I32: 2891.35 | J32: 3071.1 | K32: 3144.5 | L32: 3191.5 | M32: 10.94 | N32: 2 | O32: 4 | P32: P85关注;周涨幅≥10%;Z≥2异常;连续上涨≥3周 | Q32: 黄色关注 | R32: 来自现有SCFI真实/公开线索与演示补全长表；C_demo_interpolation不作真实事实声明
A33: 2026-01-02 | B33: 地中海航线 | C33: 2999.2 | D33: USD/TEU | E33: C_demo_interpolation | F33: 2304.51 | G33: 2432.75 | H33: 2675.65 | I33: 2891.35 | J33: 3071.1 | K33: 3144.5 | L33: 3191.5 | M33: -4.58 | N33: 1.53 | O33: 0 | P33: P85关注 | Q33: 黄色关注 | R33: 来自现有SCFI真实/公开线索与演示补全长表；C_demo_interpolation不作真实事实声明
A34: 2026-01-09 | B34: 地中海航线 | C34: 2855.4 | D34: USD/TEU | E34: C_demo_interpolation | F34: 2304.51 | G34: 2432.75 | H34: 2675.65 | I34: 2891.35 | J34: 3071.1 | K34: 3144.5 | L34: 3191.5 | M34: -4.79 | N34: 1.05 | O34: 0 | P34: 无 | Q34: 正常 | R34: 来自现有SCFI真实/公开线索与演示补全长表；C_demo_interpolation不作真实事实声明
A35: 2026-01-16 | B35: 地中海航线 | C35: 2711.6 | D35: USD/TEU | E35: C_demo_interpolation | F35: 2304.51 | G35: 2432.75 | H35: 2675.65 | I35: 2891.35 | J35: 3071.1 | K35: 3144.5 | L35: 3191.5 | M35: -5.04 | N35: 0.58 | O35: 0 | P35: 无 | Q35: 正常 | R35: 来自现有SCFI真实/公开线索与演示补全长表；C_demo_interpolation不作真实事实声明
A36: 2026-01-23 | B36: 地中海航线 | C36: 2567.8 | D36: USD/TEU | E36: C_demo_interpolation | F36: 2304.51 | G36: 2432.75 | H36: 2675.65 | I36: 2891.35 | J36: 3071.1 | K36: 3144.5 | L36: 3191.5 | M36: -5.3 | N36: 0.1 | O36: 0 | P36: 无 | Q36: 正常 | R36: 来自现有SCFI真实/公开线索与演示补全长表；C_demo_interpolation不作真实事实声明
A37: 2026-01-30 | B37: 地中海航线 | C37: 2424 | D37: USD/TEU | E37: B_public_excerpt | F37: 2304.51 | G37: 2432.75 | H37: 2675.65 | I37: 2891.35 | J37: 3071.1 | K37: 3144.5 | L37: 3191.5 | M37: -5.6 | N37: -0.37 | O37: 0 | P37: 无 | Q37: 正常 | R37: 来自现有SCFI真实/公开线索与演示补全长表；C_demo_interpolation不作真实事实声明
A38: 2026-02-06 | B38: 地中海航线 | C38: 2300.5 | D38: USD/TEU | E38: C_demo_interpolation | F38: 2304.51 | G38: 2432.75 | H38: 2675.65 | I38: 2891.35 | J38: 3071.1 | K38: 3144.5 | L38: 3191.5 | M38: -5.09 | N38: -0.78 | O38: 0 | P38: 无 | Q38: 正常 | R38: 来自现有SCFI真实/公开线索与演示补全长表；C_demo_interpolation不作真实事实声明
A39: 2026-02-13 | B39: 地中海航线 | C39: 2177 | D39: USD/TEU | E39: B_public_excerpt | F39: 2304.51 | G39: 2432.75 | H39: 2675.65 | I39: 2891.35 | J39: 3071.1 | K39: 3144.5 | L39: 3191.5 | M39: -5.37 | N39: -1.19 | O39: 0 | P39: 无 | Q39: 正常 | R39: 来自现有SCFI真实/公开线索与演示补全长表；C_demo_interpolation不作真实事实声明
A40: 2026-02-20 | B40: 地中海航线 | C40: 2211.89 | D40: USD/TEU | E40: C_demo_interpolation | F40: 2304.51 | G40: 2432.75 | H40: 2675.65 | I40: 2891.35 | J40: 3071.1 | K40: 3144.5 | L40: 3191.5 | M40: 1.6 | N40: -1.07 | O40: 1 | P40: 无 | Q40: 正常 | R40: 来自现有SCFI真实/公开线索与演示补全长表；C_demo_interpolation不作真实事实声明
... A53: 2026-05-22 | B53: 地中海航线 | C53: 3207 | D53: USD/TEU | E53: A_official | F53: 2304.51 | G53: 2432.75 | H53: 2675.65 | I53: 2891.35 | J53: 3071.1 | K53: 3144.5 | L53: 3191.5 | M53: 1.97 | N53: 2.22 | O53: 4 | P53: P95高位;Z≥2异常;连续上涨≥3周 | Q53: 红色预警 | R53: 来自现有SCFI真实/公开线索与演示补全长表；C_demo_interpolation不作真实事实声明
A54: 2025-11-28 | B54: 美西航线 | C54: 1632 | D54: USD/FEU | E54: B_public_excerpt | F54: 1924.88 | G54: 2134.75 | H54: 2510.5 | I54: 2635.5 | J54: 2766 | K54: 3045 | L54: 3145 | N54: -1.41 | O54: 0 | P54: 无 | Q54: 正常 | R54: 来自现有SCFI真实/公开线索与演示补全长表；C_demo_interpolation不作真实事实声明
A55: 2025-12-05 | B55: 美西航线 | C55: 1550 | D55: USD/FEU | E55: B_public_excerpt | F55: 1924.88 | G55: 2134.75 | H55: 2510.5 | I55: 2635.5 | J55: 2766 | K55: 3045 | L55: 3145 | M55: -5.02 | N55: -1.61 | O55: 0 | P55: 无 | Q55: 正常 | R55: 来自现有SCFI真实/公开线索与演示补全长表；C_demo_interpolation不作真实事实声明
A56: 2025-12-12 | B56: 美西航线 | C56: 1771 | D56: USD/FEU | E56: C_demo_interpolation | F56: 1924.88 | G56: 2134.75 | H56: 2510.5 | I56: 2635.5 | J56: 2766 | K56: 3045 | L56: 3145 | M56: 14.26 | N56: -1.07 | O56: 1 | P56: 周涨幅≥10% | Q56: 黄色关注 | R56: 来自现有SCFI真实/公开线索与演示补全长表；C_demo_interpolation不作真实事实声明
A57: 2025-12-19 | B57: 美西航线 | C57: 1992 | D57: USD/FEU | E57: B_public_excerpt | F57: 1924.88 | G57: 2134.75 | H57: 2510.5 | I57: 2635.5 | J57: 2766 | K57: 3045 | L57: 3145 | M57: 12.48 | N57: -0.54 | O57: 2 | P57: 周涨幅≥10% | Q57: 黄色关注 | R57: 来自现有SCFI真实/公开线索与演示补全长表；C_demo_interpolation不作真实事实声明
A58: 2025-12-26 | B58: 美西航线 | C58: 2188 | D58: USD/FEU | E58: B_public_excerpt | F58: 1924.88 | G58: 2134.75 | H58: 2510.5 | I58: 2635.5 | J58: 2766 | K58: 3045 | L58: 3145 | M58: 9.84 | N58: -0.07 | O58: 3 | P58: 连续上涨≥3周 | Q58: 黄色关注 | R58: 来自现有SCFI真实/公开线索与演示补全长表；C_demo_interpolation不作真实事实声明
A59: 2026-01-02 | B59: 美西航线 | C59: 2162 | D59: USD/FEU | E59: C_demo_interpolation | F59: 1924.88 | G59: 2134.75 | H59: 2510.5 | I59: 2635.5 | J59: 2766 | K59: 3045 | L59: 3145 | M59: -1.19 | N59: -0.13 | O59: 0 | P59: 无 | Q59: 正常 | R59: 来自现有SCFI真实/公开线索与演示补全长表；C_demo_interpolation不作真实事实声明
A60: 2026-01-09 | B60: 美西航线 | C60: 2136 | D60: USD/FEU | E60: C_demo_interpolation | F60: 1924.88 | G60: 2134.75 | H60: 2510.5 | I60: 2635.5 | J60: 2766 | K60: 3045 | L60: 3145 | M60: -1.2 | N60: -0.19 | O60: 0 | P60: 无 | Q60: 正常 | R60: 来自现有SCFI真实/公开线索与演示补全长表；C_demo_interpolation不作真实事实声明
A61: 2026-01-16 | B61: 美西航线 | C61: 2110 | D61: USD/FEU | E61: C_demo_interpolation | F61: 1924.88 | G61: 2134.75 | H61: 2510.5 | I61: 2635.5 | J61: 2766 | K61: 3045 | L61: 3145 | M61: -1.22 | N61: -0.25 | O61: 0 | P61: 无 | Q61: 正常 | R61: 来自现有SCFI真实/公开线索与演示补全长表；C_demo_interpolation不作真实事实声明
A62: 2026-01-23 | B62: 美西航线 | C62: 2084 | D62: USD/FEU | E62: B_public_excerpt | F62: 1924.88 | G62: 2134.75 | H62: 2510.5 | I62: 2635.5 | J62: 2766 | K62: 3045 | L62: 3145 | M62: -1.23 | N62: -0.32 | O62: 0 | P62: 无 | Q62: 正常 | R62: 来自现有SCFI真实/公开线索与演示补全长表；C_demo_interpolation不作真实事实声明
A63: 2026-01-30 | B63: 美西航线 | C63: 1867 | D63: USD/FEU | E63: B_public_excerpt | F63: 1924.88 | G63: 2134.75 | H63: 2510.5 | I63: 2635.5 | J63: 2766 | K63: 3045 | L63: 3145 | M63: -10.41 | N63: -0.84 | O63: 0 | P63: 无 | Q63: 正常 | R63: 来自现有SCFI真实/公开线索与演示补全长表；C_demo_interpolation不作真实事实声明
A64: 2026-02-06 | B64: 美西航线 | C64: 1801 | D64: USD/FEU | E64: B_public_excerpt | F64: 1924.88 | G64: 2134.75 | H64: 2510.5 | I64: 2635.5 | J64: 2766 | K64: 3045 | L64: 3145 | M64: -3.54 | N64: -1 | O64: 0 | P64: 无 | Q64: 正常 | R64: 来自现有SCFI真实/公开线索与演示补全长表；C_demo_interpolation不作真实事实声明
...

Sheet 最新周摘要
A1: date | B1: route_name | C1: value | D1: unit | E1: quality_level | F1: p25 | G1: p50 | H1: p75 | I1: p85 | J1: p90 | K1: p95 | L1: p99 | M1: wow_pct | N1: z_score | O1: up_streak_weeks | P1: warning_tags | Q1: warning_level | R1: source_note
A2: 2026-05-22 | B2: 欧洲航线 | C2: 1905 | D2: USD/TEU | E2: A_official | F2: 1472.25 | G2: 1550.38 | H2: 1618.56 | I2: 1648.44 | J2: 1678.12 | K2: 1784.5 | L2: 1882.75 | M2: 4.9 | N2: 2.76 | O2: 4 | P2: P95高位;Z≥2异常;连续上涨≥3周 | Q2: 红色预警 | R2: 来自现有SCFI真实/公开线索与演示补全长表；C_demo_interpolation不作真实事实声明
A3: 2026-05-22 | B3: 地中海航线 | C3: 3207 | D3: USD/TEU | E3: A_official | F3: 2304.51 | G3: 2432.75 | H3: 2675.65 | I3: 2891.35 | J3: 3071.1 | K3: 3144.5 | L3: 3191.5 | M3: 1.97 | N3: 2.22 | O3: 4 | P3: P95高位;Z≥2异常;连续上涨≥3周 | Q3: 红色预警 | R3: 来自现有SCFI真实/公开线索与演示补全长表；C_demo_interpolation不作真实事实声明
A4: 2026-05-22 | B4: 美西航线 | C4: 3154 | D4: USD/FEU | E4: A_official | F4: 1924.88 | G4: 2134.75 | H4: 2510.5 | I4: 2635.5 | J4: 2766 | K4: 3045 | L4: 3145 | M4: 1.15 | N4: 2.27 | O4: 4 | P4: P95高位;Z≥2异常;连续上涨≥3周 | Q4: 红色预警 | R4: 来自现有SCFI真实/公开线索与演示补全长表；C_demo_interpolation不作真实事实声明
A5: 2026-05-22 | B5: 美东航线 | C5: 4313 | D5: USD/FEU | E5: A_official | F5: 2707.44 | G5: 2964.38 | H5: 3468.33 | I5: 3610.75 | J5: 3751.5 | K5: 4121 | L5: 4290.75 | M5: 2.11 | N5: 2.36 | O5: 4 | P5: P95高位;Z≥2异常;连续上涨≥3周 | Q5: 红色预警 | R5: 来自现有SCFI真实/公开线索与演示补全长表；C_demo_interpolation不作真实事实声明
A6: 2026-05-22 | B6: SCFI综合指数 | C6: 2218.15 | D6: points | E6: A_official | F6: 1415.49 | G6: 1592.02 | H6: 1863.82 | I6: 1895.93 | J6: 1932.8 | K6: 2094.05 | L6: 2198.78 | M6: 3.62 | N6: 2.23 | O6: 4 | P6: P95高位;Z≥2异常;连续上涨≥3周 | Q6: 红色预警 | R6: 来自现有SCFI真实/公开线索与演示补全长表；C_demo_interpolation不作真实事实声明

Sheet 原始周度宽表
A1: date | B1: SCFI综合指数 | C1: 地中海航线 | D1: 欧洲航线 | E1: 美东航线 | F1: 美西航线 | G1: SCFI综合指数_wow_pct | H1: SCFI综合指数_4w_ma | I1: 欧洲航线_wow_pct | J1: 欧洲航线_4w_ma | K1: 地中海航线_wow_pct | L1: 地中海航线_4w_ma | M1: 美西航线_wow_pct | N1: 美西航线_4w_ma | O1: 美东航线_wow_pct | P1: 美东航线_4w_ma | Q1: 美东-美西价差_USD_FEU | R1: 地中海-欧洲价差_USD_TEU | S1: 跨太平洋均价_USD_FEU | T1: 亚欧均价_USD_TEU | U1: natural_week_start | V1: event_count | W1: event_types | X1: carriers | Y1: announced_amount_sum | Z1: event_flag
A2: 45989 | B2: 1403.13 | C2: 2232 | D2: 1404 | E2: 2428 | F2: 1632 | Q2: 796 | R2: 828 | S2: 2030 | T2: 1818 | U2: 2025-11-24 | V2: 0 | Z2: FALSE
A3: 45996 | B3: 1397.63 | C3: 2300 | D3: 1400 | E3: 2315 | F3: 1550 | G3: -0.39198079 | H3: 1400.38 | I3: -0.28490028 | J3: 1402 | K3: 3.046595 | L3: 2266 | M3: -5.0245098 | N3: 1591 | O3: -4.6540362 | P3: 2371.5 | Q3: 765 | R3: 900 | S3: 1932.5 | T3: 1850 | U3: 2025-12-01 | V3: 0 | Z3: FALSE
A4: 46003 | B4: 1475.275 | C4: 2566.5 | D4: 1466.5 | E4: 2580.5 | F4: 1771 | G4: 5.5554761 | H4: 1425.345 | I4: 4.75 | J4: 1423.5 | K4: 11.586957 | L4: 2366.1667 | M4: 14.258065 | N4: 1651 | O4: 11.468683 | P4: 2441.1667 | Q4: 809.5 | R4: 1100 | S4: 2175.75 | T4: 2016.5 | U4: 2025-12-08 | V4: 0 | Z4: FALSE
A5: 46010 | B5: 1552.92 | C5: 2833 | D5: 1533 | E5: 2846 | F5: 1992 | G5: 5.2630865 | H5: 1457.2387 | I5: 4.5346062 | J5: 1450.875 | K5: 10.383791 | L5: 2482.875 | M5: 12.478826 | N5: 1736.25 | O5: 10.288704 | P5: 2542.375 | Q5: 854 | R5: 1300 | S5: 2419 | T5: 2183 | U5: 2025-12-15 | V5: 0 | Z5: FALSE
A6: 46017 | B6: 1656.32 | C6: 3143 | D6: 1690 | E6: 3033 | F6: 2188 | G6: 6.6584241 | H6: 1520.5363 | I6: 10.241357 | J6: 1522.375 | K6: 10.942464 | L6: 2710.625 | M6: 9.8393574 | N6: 1875.25 | O6: 6.5706254 | P6: 2693.625 | Q6: 845 | R6: 1453 | S6: 2610.5 | T6: 2416.5 | U6: 2025-12-22 | V6: 0 | Z6: FALSE
A7: 46024 | B7: 1588.406 | C7: 2999.2 | D7: 1666.25 | E7: 2998.75 | F7: 2162 | G7: -4.1002946 | H7: 1568.2303 | I7: -1.4053254 | J7: 1588.9375 | K7: -4.5752466 | L7: 2885.425 | M7: -1.1882998 | N7: 2028.25 | O7: -1.129245 | P7: 2864.5625 | Q7: 836.75 | R7: 1332.95 | S7: 2580.375 | T7: 2332.725 | U7: 2025-12-29 | V7: 0 | Z7: FALSE
A8: 46031 | B8: 1520.492 | C8: 2855.4 | D8: 1642.5 | E8: 2964.5 | F8: 2136 | G8: -4.2756071 | H8: 1579.5345 | I8: -1.4253563 | J8: 1632.9375 | K8: -4.7946119 | L8: 2957.65 | M8: -1.2025902 | N8: 2119.5 | O8: -1.1421426 | P8: 2960.5625 | Q8: 828.5 | R8: 1212.9 | S8: 2550.25 | T8: 2248.95 | U8: 2026-01-05 | V8: 0 | Z8: FALSE
A9: 46038 | B9: 1452.578 | C9: 2711.6 | D9: 1618.75 | E9: 2930.25 | F9: 2110 | G9: -4.4665806 | H9: 1554.449 | I9: -1.4459665 | J9: 1654.375 | K9: -5.036072 | L9: 2927.3 | M9: -1.2172285 | N9: 2149 | O9: -1.1553382 | P9: 2981.625 | Q9: 820.25 | R9: 1092.85 | S9: 2520.125 | T9: 2165.175 | U9: 2026-01-12 | V9: 0 | Z9: FALSE
A10: 46045 | B10: 1384.664 | C10: 2567.8 | D10: 1595 | E10: 2896 | F10: 2084 | G10: -4.6754116 | H10: 1486.535 | I10: -1.4671815 | J10: 1630.625 | K10: -5.3031421 | L10: 2783.5 | M10: -1.2322275 | N10: 2123 | O10: -1.1688422 | P10: 2947.375 | Q10: 812 | R10: 972.8 | S10: 2490 | T10: 2081.4 | U10: 2026-01-19 | V10: 0 | Z10: FALSE
A11: 46052 | B11: 1316.75 | C11: 2424 | D11: 1418 | E11: 2605 | F11: 1867 | G11: -4.9047278 | H11: 1418.621 | I11: -11.097179 | J11: 1568.5625 | K11: -5.6001246 | L11: 2639.7 | M11: -10.412668 | N11: 2049.25 | O11: -10.048343 | P11: 2848.9375 | Q11: 738 | R11: 1006 | S11: 2236 | T11: 1921 | U11: 2026-01-26 | V11: 0 | Z11: FALSE
A12: 46059 | B12: 1266.56 | C12: 2300.5 | D12: 1403 | E12: 2530 | F12: 1801 | G12: -3.8116575 | H12: 1355.138 | I12: -1.0578279 | J12: 1508.6875 | K12: -5.0948845 | L12: 2500.975 | M12: -3.535083 | N12: 1965.5 | O12: -2.8790787 | P12: 2740.3125 | Q12: 729 | R12: 897.5 | S12: 2165.5 | T12: 1851.75 | U12: 2026-02-02 | V12: 0 | Z12: FALSE
A13: 46066 | B13: 1251.46 | C13: 2177 | D13: 1361 | E13: 2524 | F13: 1787 | G13: -1.1922057 | H13: 1304.8585 | I13: -2.9935852 | J13: 1444.25 | K13: -5.3683982 | L13: 2367.325 | M13: -0.77734592 | N13: 1884.75 | O13: -0.23715415 | P13: 2638.75 | Q13: 737 | R13: 816 | S13: 2155.5 | T13: 1769 | U13: 2026-02-09 | V13: 0 | Z13: FALSE
A14: 46073 | B14: 1366.1825 | C14: 2211.8889 | D14: 1425.25 | E14: 2670.75 | F14: 1902.5 | G14: 9.1670928 | H14: 1300.2381 | I14: 4.7207935 | J14: 1401.8125 | K14: 1.6026132 | L14: 2278.3472 | M14: 6.4633464 | N14: 1839.375 | O14: 5.8141838 | P14: 2582.4375 | Q14: 768.25 | R14: 786.63889 | S14: 2286.625 | T14: 1818.5694 | U14: 2026-02-16 | V14: 0 | Z14: FALSE
... A26: 46157 | B26: 2140.66 | C26: 3145 | D26: 1816 | E26: 4224 | F26: 3118 | G26: 9.5409398 | H26: 1970.3825 | I26: 13.784461 | J26: 1613.875 | K26: 27.689809 | L26: 2617.375 | M26: 10.332626 | N26: 2809 | O26: 10.807975 | P26: 3824.25 | Q26: 1106 | R26: 1329 | S26: 3671 | T26: 2480.5 | U26: 2026-05-11 | V26: 0 | Z26: FALSE
A27: 46164 | B27: 2218.15 | C27: 3207 | D27: 1905 | E27: 4313 | F27: 3154 | G27: 3.6199116 | H27: 2056.105 | I27: 4.9008811 | J27: 1715.875 | K27: 1.9713831 | L27: 2814.125 | M27: 1.1545863 | N27: 2951 | O27: 2.1070076 | P27: 4010 | Q27: 1159 | R27: 1302 | S27: 3733.5 | T27: 2556 | U27: 2026-05-18 | V27: 1 | W27: PSS | X27: Maersk | Y27: 1000 | Z27: TRUE

Sheet 质量等级来源长表
A1: date | B1: natural_week_start | C1: natural_week_end | D1: route_name | E1: observed_value | F1: value_used_for_demo | G1: unit | H1: source_value_layer | I1: demo_fill_method | J1: is_demo_filled | K1: data_quality_level | L1: record_status | M1: source_type
A2: 45989 | B2: 2025-11-24 | C2: 2025-11-30 | D2: SCFI综合指数 | E2: 1403.13 | F2: 1403.13 | G2: points | H2: A/B_public_observed_or_pending_recheck | I2: observed_value_kept | J2: FALSE | K2: B | L2: collected_public_excerpt | M2: batch03_04_public_excerpt
A3: 45996 | B3: 2025-12-01 | C3: 2025-12-07 | D3: SCFI综合指数 | E3: 1397.63 | F3: 1397.63 | G3: points | H3: A/B_public_observed_or_pending_recheck | I3: observed_value_kept | J3: FALSE | K3: B | L3: collected_public_excerpt | M3: batch03_04_public_excerpt
A4: 46003 | B4: 2025-12-08 | C4: 2025-12-14 | D4: SCFI综合指数 | F4: 1475.275 | G4: points | H4: demo_interpolation_fill | I4: linear_interpolation_or_boundary_nearest | J4: TRUE | K4: PENDING | L4: placeholder_pending | M4: placeholder
A5: 46010 | B5: 2025-12-15 | C5: 2025-12-21 | D5: SCFI综合指数 | E5: 1552.92 | F5: 1552.92 | G5: points | H5: A/B_public_observed_or_pending_recheck | I5: observed_value_kept | J5: FALSE | K5: B | L5: collected_public_excerpt | M5: batch03_04_public_excerpt
A6: 46017 | B6: 2025-12-22 | C6: 2025-12-28 | D6: SCFI综合指数 | E6: 1656.32 | F6: 1656.32 | G6: points | H6: A/B_public_observed_or_pending_recheck | I6: observed_value_kept | J6: FALSE | K6: B | L6: collected_public_excerpt | M6: batch03_04_public_excerpt
A7: 46024 | B7: 2025-12-29 | C7: 2026-01-04 | D7: SCFI综合指数 | F7: 1588.406 | G7: points | H7: demo_interpolation_fill | I7: linear_interpolation_or_boundary_nearest | J7: TRUE | K7: A_publication_suspended | L7: official_publication_suspended | M7: official_publication_calendar
A8: 46031 | B8: 2026-01-05 | C8: 2026-01-11 | D8: SCFI综合指数 | F8: 1520.492 | G8: points | H8: demo_interpolation_fill | I8: linear_interpolation_or_boundary_nearest | J8: TRUE | K8: PENDING | L8: placeholder_pending | M8: placeholder
A9: 46038 | B9: 2026-01-12 | C9: 2026-01-18 | D9: SCFI综合指数 | F9: 1452.578 | G9: points | H9: demo_interpolation_fill | I9: linear_interpolation_or_boundary_nearest | J9: TRUE | K9: PENDING | L9: placeholder_pending | M9: placeholder
A10: 46045 | B10: 2026-01-19 | C10: 2026-01-25 | D10: SCFI综合指数 | F10: 1384.664 | G10: points | H10: demo_interpolation_fill | I10: linear_interpolation_or_boundary_nearest | J10: TRUE | K10: B | L10: collected_public_excerpt | M10: batch03_04_public_excerpt
A11: 46052 | B11: 2026-01-26 | C11: 2026-02-01 | D11: SCFI综合指数 | E11: 1316.75 | F11: 1316.75 | G11: points | H11: A/B_public_observed_or_pending_recheck | I11: observed_value_kept | J11: FALSE | K11: B | L11: collected_public_excerpt | M11: batch03_04_public_excerpt
A12: 46059 | B12: 2026-02-02 | C12: 2026-02-08 | D12: SCFI综合指数 | E12: 1266.56 | F12: 1266.56 | G12: points | H12: A/B_public_observed_or_pending_recheck | I12: observed_value_kept | J12: FALSE | K12: B | L12: collected_public_excerpt | M12: batch03_04_public_excerpt
A13: 46066 | B13: 2026-02-09 | C13: 2026-02-15 | D13: SCFI综合指数 | E13: 1251.46 | F13: 1251.46 | G13: points | H13: A/B_public_observed_or_pending_recheck | I13: observed_value_kept | J13: FALSE | K13: B | L13: collected_public_excerpt | M13: batch03_04_public_excerpt
A14: 46073 | B14: 2026-02-16 | C14: 2026-02-22 | D14: SCFI综合指数 | F14: 1366.1825 | G14: points | H14: demo_interpolation_fill | I14: linear_interpolation_or_boundary_nearest | J14: TRUE | K14: PENDING | L14: placeholder_pending | M14: placeholder
A15: 46080 | B15: 2026-02-23 | C15: 2026-03-01 | D15: SCFI综合指数 | F15: 1480.905 | G15: points | H15: demo_interpolation_fill | I15: linear_interpolation_or_boundary_nearest | J15: TRUE | K15: PENDING | L15: placeholder_pending | M15: placeholder
A16: 46087 | B16: 2026-03-02 | C16: 2026-03-08 | D16: SCFI综合指数 | F16: 1595.6275 | G16: points | H16: demo_interpolation_fill | I16: linear_interpolation_or_boundary_nearest | J16: TRUE | K16: PENDING | L16: placeholder_pending | M16: placeholder
A17: 46094 | B17: 2026-03-09 | C17: 2026-03-15 | D17: SCFI综合指数 | E17: 1710.35 | F17: 1710.35 | G17: points | H17: A/B_public_observed_or_pending_recheck | I17: observed_value_kept | J17: FALSE | K17: B_pending_source_recheck | L17: legacy_value_pending_source_recheck | M17: legacy_public_clue_needs_source_recheck
A18: 46101 | B18: 2026-03-16 | C18: 2026-03-22 | D18: SCFI综合指数 | E18: 1706.95 | F18: 1706.95 | G18: points | H18: A/B_public_observed_or_pending_recheck | I18: observed_value_kept | J18: FALSE | K18: B_pending_source_recheck | L18: legacy_value_pending_source_recheck | M18: legacy_public_clue_needs_source_recheck
A19: 46108 | B19: 2026-03-23 | C19: 2026-03-29 | D19: SCFI综合指数 | F19: 1768.2233 | G19: points | H19: demo_interpolation_fill | I19: linear_interpolation_or_boundary_nearest | J19: TRUE | K19: PENDING | L19: placeholder_pending | M19: placeholder
A20: 46115 | B20: 2026-03-30 | C20: 2026-04-05 | D20: SCFI综合指数 | F20: 1829.4967 | G20: points | H20: demo_interpolation_fill | I20: linear_interpolation_or_boundary_nearest | J20: TRUE | K20: PENDING | L20: placeholder_pending | M20: placeholder
A21: 46122 | B21: 2026-04-06 | C21: 2026-04-12 | D21: SCFI综合指数 | E21: 1890.77 | F21: 1890.77 | G21: points | H21: A/B_public_observed_or_pending_recheck | I21: observed_value_kept | J21: FALSE | K21: B_pending_source_recheck | L21: legacy_value_pending_source_recheck | M21: legacy_public_clue_needs_source_recheck
A22: 46129 | B22: 2026-04-13 | C22: 2026-04-19 | D22: SCFI综合指数 | E22: 1886.54 | F22: 1886.54 | G22: points | H22: A/B_public_observed_or_pending_recheck | I22: observed_value_kept | J22: FALSE | K22: B_pending_original_text | L22: collected_public_excerpt_pending_original_text | M22: public_excerpt_batch_01
A23: 46136 | B23: 2026-04-20 | C23: 2026-04-26 | D23: SCFI综合指数 | E23: 1875.26 | F23: 1875.26 | G23: points | H23: A/B_public_observed_or_pending_recheck | I23: observed_value_kept | J23: FALSE | K23: B_pending_original_text | L23: collected_public_excerpt_pending_original_text | M23: public_excerpt_batch_01
A24: 46143 | B24: 2026-04-27 | C24: 2026-05-03 | D24: SCFI综合指数 | E24: 1911.4 | F24: 1911.4 | G24: points | H24: A/B_public_observed_or_pending_recheck | I24: observed_value_kept | J24: FALSE | K24: B_pending_original_text | L24: collected_public_excerpt_pending_original_text | M24: public_excerpt_batch_01
A25: 46150 | B25: 2026-05-04 | C25: 2026-05-10 | D25: SCFI综合指数 | E25: 1954.21 | F25: 1954.21 | G25: points | H25: A/B_public_observed_or_pending_recheck | I25: observed_value_kept | J25: FALSE | K25: B_pending_original_text | L25: collected_public_excerpt_pending_original_text | M25: public_excerpt_batch_01
A26: 46157 | B26: 2026-05-11 | C26: 2026-05-17 | D26: SCFI综合指数 | E26: 2140.66 | F26: 2140.66 | G26: points | H26: A/B_public_observed_or_pending_recheck | I26: observed_value_kept | J26: FALSE | K26: A(composite_only)/B_pending_original_text(route_values) | L26: partial_composite_verified_routes_public_excerpt_pending | M26: official_single_page_table_for_composite_plus_unverified_public_route_clues
A27: 46164 | B27: 2026-05-18 | C27: 2026-05-24 | D27: SCFI综合指数 | E27: 2218.15 | F27: 2218.15 | G27: points | H27: A/B_public_observed_or_pending_recheck | I27: observed_value_kept | J27: FALSE | K27: A/B | L27: partial_or_complete_collected | M27: official_single_page_plus_public_repost
A28: 45989 | B28: 2025-11-24 | C28: 2025-11-30 | D28: 地中海航线 | E28: 2232 | F28: 2232 | G28: USD/TEU | H28: A/B_public_observed_or_pending_recheck | I28: observed_value_kept | J28: FALSE | K28: B | L28: collected_public_excerpt | M28: batch03_04_public_excerpt
A29: 45996 | B29: 2025-12-01 | C29: 2025-12-07 | D29: 地中海航线 | E29: 2300 | F29: 2300 | G29: USD/TEU | H29: A/B_public_observed_or_pending_recheck | I29: observed_value_kept | J29: FALSE | K29: B | L29: collected_public_excerpt | M29: batch03_04_public_excerpt
A30: 46003 | B30: 2025-12-08 | C30: 2025-12-14 | D30: 地中海航线 | F30: 2566.5 | G30: USD/TEU | H30: demo_interpolation_fill | I30: linear_interpolation_or_boundary_nearest | J30: TRUE | K30: PENDING | L30: placeholder_pending | M30: placeholder
A31: 46010 | B31: 2025-12-15 | C31: 2025-12-21 | D31: 地中海航线 | E31: 2833 | F31: 2833 | G31: USD/TEU | H31: A/B_public_observed_or_pending_recheck | I31: observed_value_kept | J31: FALSE | K31: B | L31: collected_public_excerpt | M31: batch03_04_public_excerpt
A32: 46017 | B32: 2025-12-22 | C32: 2025-12-28 | D32: 地中海航线 | E32: 3143 | F32: 3143 | G32: USD/TEU | H32: A/B_public_observed_or_pending_recheck | I32: observed_value_kept | J32: FALSE | K32: B | L32: collected_public_excerpt | M32: batch03_04_public_excerpt
A33: 46024 | B33: 2025-12-29 | C33: 2026-01-04 | D33: 地中海航线 | F33: 2999.2 | G33: USD/TEU | H33: demo_interpolation_fill | I33: linear_interpolation_or_boundary_nearest | J33: TRUE | K33: A_publication_suspended | L33: official_publication_suspended | M33: official_publication_calendar
A34: 46031 | B34: 2026-01-05 | C34: 2026-01-11 | D34: 地中海航线 | F34: 2855.4 | G34: USD/TEU | H34: demo_interpolation_fill | I34: linear_interpolation_or_boundary_nearest | J34: TRUE | K34: PENDING | L34: placeholder_pending | M34: placeholder
A35: 46038 | B35: 2026-01-12 | C35: 2026-01-18 | D35: 地中海航线 | F35: 2711.6 | G35: USD/TEU | H35: demo_interpolation_fill | I35: linear_interpolation_or_boundary_nearest | J35: TRUE | K35: PENDING | L35: placeholder_pending | M35: placeholder
A36: 46045 | B36: 2026-01-19 | C36: 2026-01-25 | D36: 地中海航线 | F36: 2567.8 | G36: USD/TEU | H36: demo_interpolation_fill | I36: linear_interpolation_or_boundary_nearest | J36: TRUE | K36: B | L36: collected_public_excerpt | M36: batch03_04_public_excerpt
A37: 46052 | B37: 2026-01-26 | C37: 2026-02-01 | D37: 地中海航线 | E37: 2424 | F37: 2424 | G37: USD/TEU | H37: A/B_public_observed_or_pending_recheck | I37: observed_value_kept | J37: FALSE | K37: B | L37: collected_public_excerpt | M37: batch03_04_public_excerpt
A38: 46059 | B38: 2026-02-02 | C38: 2026-02-08 | D38: 地中海航线 | F38: 2300.5 | G38: USD/TEU | H38: demo_interpolation_fill | I38: linear_interpolation_or_boundary_nearest | J38: TRUE | K38: B | L38: collected_public_excerpt | M38: batch03_04_public_excerpt
A39: 46066 | B39: 2026-02-09 | C39: 2026-02-15 | D39: 地中海航线 | E39: 2177 | F39: 2177 | G39: USD/TEU | H39: A/B_public_observed_or_pending_recheck | I39: observed_value_kept | J39: FALSE | K39: B | L39: collected_public_excerpt | M39: batch03_04_public_excerpt
A40: 46073 | B40: 2026-02-16 | C40: 2026-02-22 | D40: 地中海航线 | F40: 2211.8889 | G40: USD/TEU | H40: demo_interpolation_fill | I40: linear_interpolation_or_boundary_nearest | J40: TRUE | K40: PENDING | L40: placeholder_pending | M40: placeholder
...

Sheet Excel公式审计示例
A1: 指标 | B1: 航线 | C1: 公式说明 | D1: Excel公式样例 | E1: 状态
A2: P95分位 | B2: SCFI综合指数 | C2: 最近26周该航线数值的95分位 | D2: =PERCENTILE.INC('原始周度宽表'!B$2:B$27,0.95) | E2: 可运行公式
A3: 周环比 | B3: SCFI综合指数 | C3: 本周相对上周变化百分比 | D3: =('原始周度宽表'!B$27/'原始周度宽表'!B$26-1)*100 | E3: 可运行公式
A4: Z分数 | B4: SCFI综合指数 | C4: 本周值相对最近26周均值和样本标准差的标准化偏离 | D4: =('原始周度宽表'!B$27-AVERAGE('原始周度宽表'!B$2:B$27))/STDEV.S('原始周度宽表'!B$2:B$27) | E4: 可运行公式
A5: 连续上涨周数 | B5: SCFI综合指数 | C5: 从最新周向前逐周检查，遇到非上涨即重置；样例最多回看5周 | D5: =IF('原始周度宽表'!B$27<='原始周度宽表'!B$26,0,IF('原始周度宽表'!B$26<='原始周度宽表'!B$25,1,IF('原始周度宽表'!B$25<='原始周度宽表'!B$24,2,IF('原始周度宽表'!B$24<='原始周度宽表'!B$23,3,IF('原始周度宽表'!B$23<='原始周度宽表'!B$22,4,5))))) | E5: 可运行公式
A6: P95分位 | B6: 欧洲航线 | C6: 最近26周该航线数值的95分位 | D6: =PERCENTILE.INC('原始周度宽表'!D$2:D$27,0.95) | E6: 可运行公式
A7: 周环比 | B7: 欧洲航线 | C7: 本周相对上周变化百分比 | D7: =('原始周度宽表'!D$27/'原始周度宽表'!D$26-1)*100 | E7: 可运行公式
A8: Z分数 | B8: 欧洲航线 | C8: 本周值相对最近26周均值和样本标准差的标准化偏离 | D8: =('原始周度宽表'!D$27-AVERAGE('原始周度宽表'!D$2:D$27))/STDEV.S('原始周度宽表'!D$2:D$27) | E8: 可运行公式
A9: 连续上涨周数 | B9: 欧洲航线 | C9: 从最新周向前逐周检查，遇到非上涨即重置；样例最多回看5周 | D9: =IF('原始周度宽表'!D$27<='原始周度宽表'!D$26,0,IF('原始周度宽表'!D$26<='原始周度宽表'!D$25,1,IF('原始周度宽表'!D$25<='原始周度宽表'!D$24,2,IF('原始周度宽表'!D$24<='原始周度宽表'!D$23,3,IF('原始周度宽表'!D$23<='原始周度宽表'!D$22,4,5))))) | E9: 可运行公式
A10: P95分位 | B10: 地中海航线 | C10: 最近26周该航线数值的95分位 | D10: =PERCENTILE.INC('原始周度宽表'!C$2:C$27,0.95) | E10: 可运行公式
A11: 周环比 | B11: 地中海航线 | C11: 本周相对上周变化百分比 | D11: =('原始周度宽表'!C$27/'原始周度宽表'!C$26-1)*100 | E11: 可运行公式
A12: Z分数 | B12: 地中海航线 | C12: 本周值相对最近26周均值和样本标准差的标准化偏离 | D12: =('原始周度宽表'!C$27-AVERAGE('原始周度宽表'!C$2:C$27))/STDEV.S('原始周度宽表'!C$2:C$27) | E12: 可运行公式
A13: 连续上涨周数 | B13: 地中海航线 | C13: 从最新周向前逐周检查，遇到非上涨即重置；样例最多回看5周 | D13: =IF('原始周度宽表'!C$27<='原始周度宽表'!C$26,0,IF('原始周度宽表'!C$26<='原始周度宽表'!C$25,1,IF('原始周度宽表'!C$25<='原始周度宽表'!C$24,2,IF('原始周度宽表'!C$24<='原始周度宽表'!C$23,3,IF('原始周度宽表'!C$23<='原始周度宽表'!C$22,4,5))))) | E13: 可运行公式
A14: P95分位 | B14: 美西航线 | C14: 最近26周该航线数值的95分位 | D14: =PERCENTILE.INC('原始周度宽表'!F$2:F$27,0.95) | E14: 可运行公式
A15: 周环比 | B15: 美西航线 | C15: 本周相对上周变化百分比 | D15: =('原始周度宽表'!F$27/'原始周度宽表'!F$26-1)*100 | E15: 可运行公式
A16: Z分数 | B16: 美西航线 | C16: 本周值相对最近26周均值和样本标准差的标准化偏离 | D16: =('原始周度宽表'!F$27-AVERAGE('原始周度宽表'!F$2:F$27))/STDEV.S('原始周度宽表'!F$2:F$27) | E16: 可运行公式
A17: 连续上涨周数 | B17: 美西航线 | C17: 从最新周向前逐周检查，遇到非上涨即重置；样例最多回看5周 | D17: =IF('原始周度宽表'!F$27<='原始周度宽表'!F$26,0,IF('原始周度宽表'!F$26<='原始周度宽表'!F$25,1,IF('原始周度宽表'!F$25<='原始周度宽表'!F$24,2,IF('原始周度宽表'!F$24<='原始周度宽表'!F$23,3,IF('原始周度宽表'!F$23<='原始周度宽表'!F$22,4,5))))) | E17: 可运行公式
A18: P95分位 | B18: 美东航线 | C18: 最近26周该航线数值的95分位 | D18: =PERCENTILE.INC('原始周度宽表'!E$2:E$27,0.95) | E18: 可运行公式
A19: 周环比 | B19: 美东航线 | C19: 本周相对上周变化百分比 | D19: =('原始周度宽表'!E$27/'原始周度宽表'!E$26-1)*100 | E19: 可运行公式
A20: Z分数 | B20: 美东航线 | C20: 本周值相对最近26周均值和样本标准差的标准化偏离 | D20: =('原始周度宽表'!E$27-AVERAGE('原始周度宽表'!E$2:E$27))/STDEV.S('原始周度宽表'!E$2:E$27) | E20: 可运行公式
A21: 连续上涨周数 | B21: 美东航线 | C21: 从最新周向前逐周检查，遇到非上涨即重置；样例最多回看5周 | D21: =IF('原始周度宽表'!E$27<='原始周度宽表'!E$26,0,IF('原始周度宽表'!E$26<='原始周度宽表'!E$25,1,IF('原始周度宽表'!E$25<='原始周度宽表'!E$24,2,IF('原始周度宽表'!E$24<='原始周度宽表'!E$23,3,IF('原始周度宽表'!E$23<='原始周度宽表'!E$22,4,5))))) | E21: 可运行公式

Sheet 公式说明
A1: 指标 | B1: 计算逻辑 | C1: Excel公式原则 | D1: 备注
A2: P25/P50/P75/P85/P90/P95/P99 | B2: 对同一航线最近26周value计算分位数 | C2: PERCENTILE.INC(最近26周范围, 分位参数) | D2: 用于判断历史相对位置
A3: 周环比 | B3: 本周value/上周value-1 | C3: =(本周单元格/上周单元格-1)*100 | D3: 首周为空
A4: Z分数 | B4: (本周value-最近26周均值)/最近26周样本标准差 | C4: =(本周值-AVERAGE(范围))/STDEV.S(范围) | D4: 用于识别异常偏离
A5: 连续上涨周数 | B5: 从最新周向前检查，遇到非上涨即重置 | C5: 嵌套IF或辅助列递推 | D5: 本审计样例采用嵌套IF，最多展示5周
A6: 预警标签 | B6: 分位、周环比、Z分数、连续上涨组合打标 | C6: TEXTJOIN + IF组合 | D6: P85/P95、涨幅、Z≥2/3、连续上涨≥3/5周

Sheet 公式审计_可运行样例
A1: 航线 | B1: 最新值 | C1: P95公式 | D1: 周环比公式 | E1: Z分数公式 | F1: 连续上涨公式 | G1: 预警标签公式
A2: SCFI综合指数 | B2: ='原始周度宽表'!B$27 | C2: =PERCENTILE.INC('原始周度宽表'!B$2:B$27,0.95) | D2: =('原始周度宽表'!B$27/'原始周度宽表'!B$26-1)*100 | E2: =('原始周度宽表'!B$27-AVERAGE('原始周度宽表'!B$2:B$27))/STDEV.S('原始周度宽表'!B$2:B$27) | F2: =IF('原始周度宽表'!B$27<='原始周度宽表'!B$26,0,IF('原始周度宽表'!B$26<='原始周度宽表'!B$25,1,IF('原始周度宽表'!B$25<='原始周度宽表'!B$24,2,IF('原始周度宽表'!B$24<='原始周度宽表'!B$23,3,IF('原始周度宽表'!B$23<='原始周度宽表'!B$22,4,5))))) | G2: =TEXTJOIN(";",TRUE,IF(B2>=C2,"P95高位",""),IF(E2>=2,"Z≥2异常",""),IF(F2>=3,"连续上涨≥3周",""),IF(D2<=-5,"周环比下跌≥5%",""))
A3: 欧洲航线 | B3: ='原始周度宽表'!D$27 | C3: =PERCENTILE.INC('原始周度宽表'!D$2:D$27,0.95) | D3: =('原始周度宽表'!D$27/'原始周度宽表'!D$26-1)*100 | E3: =('原始周度宽表'!D$27-AVERAGE('原始周度宽表'!D$2:D$27))/STDEV.S('原始周度宽表'!D$2:D$27) | F3: =IF('原始周度宽表'!D$27<='原始周度宽表'!D$26,0,IF('原始周度宽表'!D$26<='原始周度宽表'!D$25,1,IF('原始周度宽表'!D$25<='原始周度宽表'!D$24,2,IF('原始周度宽表'!D$24<='原始周度宽表'!D$23,3,IF('原始周度宽表'!D$23<='原始周度宽表'!D$22,4,5))))) | G3: =TEXTJOIN(";",TRUE,IF(B3>=C3,"P95高位",""),IF(E3>=2,"Z≥2异常",""),IF(F3>=3,"连续上涨≥3周",""),IF(D3<=-5,"周环比下跌≥5%",""))
A4: 地中海航线 | B4: ='原始周度宽表'!C$27 | C4: =PERCENTILE.INC('原始周度宽表'!C$2:C$27,0.95) | D4: =('原始周度宽表'!C$27/'原始周度宽表'!C$26-1)*100 | E4: =('原始周度宽表'!C$27-AVERAGE('原始周度宽表'!C$2:C$27))/STDEV.S('原始周度宽表'!C$2:C$27) | F4: =IF('原始周度宽表'!C$27<='原始周度宽表'!C$26,0,IF('原始周度宽表'!C$26<='原始周度宽表'!C$25,1,IF('原始周度宽表'!C$25<='原始周度宽表'!C$24,2,IF('原始周度宽表'!C$24<='原始周度宽表'!C$23,3,IF('原始周度宽表'!C$23<='原始周度宽表'!C$22,4,5))))) | G4: =TEXTJOIN(";",TRUE,IF(B4>=C4,"P95高位",""),IF(E4>=2,"Z≥2异常",""),IF(F4>=3,"连续上涨≥3周",""),IF(D4<=-5,"周环比下跌≥5%",""))
A5: 美西航线 | B5: ='原始周度宽表'!F$27 | C5: =PERCENTILE.INC('原始周度宽表'!F$2:F$27,0.95) | D5: =('原始周度宽表'!F$27/'原始周度宽表'!F$26-1)*100 | E5: =('原始周度宽表'!F$27-AVERAGE('原始周度宽表'!F$2:F$27))/STDEV.S('原始周度宽表'!F$2:F$27) | F5: =IF('原始周度宽表'!F$27<='原始周度宽表'!F$26,0,IF('原始周度宽表'!F$26<='原始周度宽表'!F$25,1,IF('原始周度宽表'!F$25<='原始周度宽表'!F$24,2,IF('原始周度宽表'!F$24<='原始周度宽表'!F$23,3,IF('原始周度宽表'!F$23<='原始周度宽表'!F$22,4,5))))) | G5: =TEXTJOIN(";",TRUE,IF(B5>=C5,"P95高位",""),IF(E5>=2,"Z≥2异常",""),IF(F5>=3,"连续上涨≥3周",""),IF(D5<=-5,"周环比下跌≥5%",""))
A6: 美东航线 | B6: ='原始周度宽表'!E$27 | C6: =PERCENTILE.INC('原始周度宽表'!E$2:E$27,0.95) | D6: =('原始周度宽表'!E$27/'原始周度宽表'!E$26-1)*100 | E6: =('原始周度宽表'!E$27-AVERAGE('原始周度宽表'!E$2:E$27))/STDEV.S('原始周度宽表'!E$2:E$27) | F6: =IF('原始周度宽表'!E$27<='原始周度宽表'!E$26,0,IF('原始周度宽表'!E$26<='原始周度宽表'!E$25,1,IF('原始周度宽表'!E$25<='原始周度宽表'!E$24,2,IF('原始周度宽表'!E$24<='原始周度宽表'!E$23,3,IF('原始周度宽表'!E$23<='原始周度宽表'!E$22,4,5))))) | G6: =TEXTJOIN(";",TRUE,IF(B6>=C6,"P95高位",""),IF(E6>=2,"Z≥2异常",""),IF(F6>=3,"连续上涨≥3周",""),IF(D6<=-5,"周环比下跌≥5%",""))
